2023-04-02 21:35:37.581 WARNING (Recorder) [homeassistant.components.recorder.util] The system could not validate that the sqlite3 database at //config/home-assistant_v2.db was shutdown cleanly
2023-04-02 21:35:39.285 WARNING (Recorder) [homeassistant.components.recorder.migration] Database is about to upgrade from schema version: 35 to: 33
2023-04-02 21:36:35.033 ERROR (MainThread) [aiohttp.server] Error handling request
Traceback (most recent call last):
  File "/usr/local/lib/python3.10/site-packages/aiohttp/web_protocol.py", line 334, in data_received
    messages, upgraded, tail = self._request_parser.feed_data(data)
  File "aiohttp/_http_parser.pyx", line 551, in aiohttp._http_parser.HttpParser.feed_data
aiohttp.http_exceptions.BadStatusLine: 400, message="Bad status line 'Invalid method encountered'"
2023-04-02 21:38:21.632 ERROR (MainThread) [aiohttp.server] Error handling request
Traceback (most recent call last):
  File "/usr/local/lib/python3.10/site-packages/aiohttp/web_protocol.py", line 334, in data_received
    messages, upgraded, tail = self._request_parser.feed_data(data)
  File "aiohttp/_http_parser.pyx", line 551, in aiohttp._http_parser.HttpParser.feed_data
aiohttp.http_exceptions.BadStatusLine: 400, message="Bad status line 'Invalid method encountered'"
2023-04-02 21:38:21.635 ERROR (MainThread) [aiohttp.server] Error handling request
Traceback (most recent call last):
  File "/usr/local/lib/python3.10/site-packages/aiohttp/web_protocol.py", line 334, in data_received
    messages, upgraded, tail = self._request_parser.feed_data(data)
  File "aiohttp/_http_parser.pyx", line 551, in aiohttp._http_parser.HttpParser.feed_data
aiohttp.http_exceptions.BadStatusLine: 400, message="Bad status line 'Invalid method encountered'"
2023-04-02 21:38:33.054 ERROR (MainThread) [aiohttp.server] Error handling request
Traceback (most recent call last):
  File "/usr/local/lib/python3.10/site-packages/aiohttp/web_protocol.py", line 334, in data_received
    messages, upgraded, tail = self._request_parser.feed_data(data)
  File "aiohttp/_http_parser.pyx", line 551, in aiohttp._http_parser.HttpParser.feed_data
aiohttp.http_exceptions.BadStatusLine: 400, message="Bad status line 'Invalid method encountered'"
2023-04-02 21:53:59.604 WARNING (Thread-6 (_thread_main)) [homeassistant.components.mqtt.client] Disconnected from MQTT server 192.168.18.47:1883 (7)
